Workbook

Sheet Blog
C2: ∆ Gini | D2: ∆ Unfairness | F2: Year | G2: Very Unfair | H2: Unfair | I2: Unfair or Very Unfair | J2: Gini
B3: Arg | C3: =+'Fig1'!D3-'Fig1'!C3 -> -0.0789866 | D3: =+'Fig2'!D3-'Fig2'!C3 -> -22.17575 | F3: 1997 | G3: 28.757 | H3: 51.633 | I3: 80.39007 | J3: 0.54566875
B4: Bol | C4: =+'Fig1'!D4-'Fig1'!C4 -> -0.12098066 | D4: =+'Fig2'!D4-'Fig2'!C4 -> -24.6143
B5: Bra | C5: =+'Fig1'!D5-'Fig1'!C5 -> -0.05745938 | D5: =+'Fig2'!D5-'Fig2'!C5 -> -5.01253
B6: Chl | C6: =+'Fig1'!D6-'Fig1'!C6 -> -0.04254513 | D6: =+'Fig2'!D6-'Fig2'!C6 -> -0.44024 | F6: 2000
B7: Col | C7: =+'Fig1'!D7-'Fig1'!C7 -> -0.0476708 | D7: =+'Fig2'!D7-'Fig2'!C7 -> -3.73114 | G7: 37.4349 | H7: 51.4348 | I7: 88.86971 | J7: 0.53624686
B8: Cri | C8: =+'Fig1'!D8-'Fig1'!C8 -> 0.01079587 | D8: =+'Fig2'!D8-'Fig2'!C8 -> 9.13719 | G8: 33.0832 | H8: 53.5236 | I8: 86.6068 | J8: 0.53747916
B9: Dom | C9: =+'Fig1'!D9-'Fig1'!C9 -> -0.03045234 | D9: =+'Fig2'!D9-'Fig2'!C9 -> -1.71831
B10: Ecu | C10: =+'Fig1'!D10-'Fig1'!C10 -> -0.07702276 | D10: =+D22+15 -> -33.90605
B11: Gtm | C11: =+'Fig1'!D11-'Fig1'!C11 -> -0.06232496 | D11: =+'Fig2'!D11-'Fig2'!C11 -> -11.42488 | F11: 2005
B12: Hnd | C12: =+'Fig1'!D12-'Fig1'!C12 -> -0.05108075 | D12: =+'Fig2'!D12-'Fig2'!C12 -> 4.56532
B13: Mex | C13: =+'Fig1'!D13-'Fig1'!C13 -> -0.02106313 | D13: =+'Fig2'!D13-'Fig2'!C13 -> -12.03515 | G13: 27.5915 | H13: 50.1617 | I13: 77.75323 | J13: 0.50623315
B14: Nic | C14: =+'Fig1'!D14-'Fig1'!C14 -> -0.06577222 | D14: =+'Fig2'!D14-'Fig2'!C14 -> -23.4406
B15: Pan | C15: =+'Fig1'!D15-'Fig1'!C15 -> -0.00967341 | D15: =+'Fig2'!D15-'Fig2'!C15 -> -28.58135 | G15: 24.4256 | H15: 53.4254 | I15: 77.85107 | J15: 0.48962709
B16: Per | C16: =+'Fig1'!D16-'Fig1'!C16 -> -0.06469789 | D16: =+'Fig2'!D16-'Fig2'!C16 -> -4.23477 | F16: 2010 | G16: 24.7166 | H16: 53.232 | I16: 77.94858 | J16: 0.48464448
B17: Pry | C17: =+'Fig1'!D17-'Fig1'!C17 -> -0.09038839 | D17: =+'Fig2'!D17-'Fig2'!C17 -> -3.03842 | G17: 24.4698 | H17: 54.9853 | I17: 79.45507 | J17: 0.48130264
B18: Slv | C18: =+'Fig1'!D18-'Fig1'!C18 -> -0.08022926 | D18: =+'Fig2'!D18-'Fig2'!C18 -> -10.31834
B19: Ury | C19: =+'Fig1'!D19-'Fig1'!C19 -> -0.04571893 | D19: =+'Fig2'!D19-'Fig2'!C19 -> -29.46806 | G19: 25.6374 | H19: 47.2726 | I19: 72.90995 | J19: 0.47656149
B20: Ven | C20: =+'Fig1'!D20-'Fig1'!C20 -> -0.07325419 | D20: =+'Fig2'!D20-'Fig2'!C20 -> -18.91019
F21: 2015 | G21: 25.8284 | H21: 49.2563 | I21: 75.08463 | J21: 0.46712735
B22: Real Ecuador | D22: -48.90605
B25: Corr(Gini,Fairness) | D25: =+CORREL(I3:I21,J3:J21) -> 0.7973019
B26: Change Gini | D26: =+(J21/J3)-1 -> -0.14393604

Sheet Fig1
C2: Gini 2002 | D2: Gini 2013
B3: Argentina | C3: 0.501825 | D3: 0.4228384
B4: Bolivia | C4: 0.601584 | D4: 0.48060334
B5: Brazil | C5: 0.586198 | D5: 0.52873862
B6: Chile | C6: 0.514899 | D6: 0.47235387
B7: Colombia | C7: 0.582549 | D7: 0.5348782
B8: Costa Rica | C8: 0.480961 | D8: 0.49175687
B9: Dominican Republic | C9: 0.501168 | D9: 0.47071566
B10: Ecuador | C10: 0.549913 | D10: 0.47289024
B11: Guatemala | C11: 0.548895 | D11: 0.48657004
B12: Honduras | C12: 0.587797 | D12: 0.53671625
B13: Mexico | C13: 0.512467 | D13: 0.49140387
B14: Nicaragua | C14: 0.531416 | D14: 0.46564378
... B20: Venezuela | C20: 0.481547 | D20: 0.40829281
B22: 45 line
B23: 0.4
B24: 0.6
C27: 2002 Gini | D27: Comes from | F27: 2013 Gini | G27: Comes from
B28: arg | C28: 0.501825 | D28: 2004 | F28: 0.42284 | G28: 2013
B29: bol | C29: 0.601584 | D29: 2002 | F29: 0.4806 | G29: 2013
B30: bra | C30: 0.586198 | D30: 2002 | F30: 0.52874 | G30: 2013
B31: chl | C31: 0.514899 | D31: 2003 | F31: 0.47263 | G31: 2013
B32: col | C32: 0.582549 | D32: 2002 | F32: 0.53488 | G32: 2013
B33: cri | C33: 0.480961 | D33: 2010 | F33: 0.49176 | G33: 2013
B34: dom | C34: 0.501168 | D34: 2002 | F34: 0.47072 | G34: 2013
B35: ecu | C35: 0.549913 | D35: 2003 | F35: 0.47289 | G35: 2013
B36: gtm | C36: 0.548895 | D36: 2006 | F36: 0.48657 | G36: 2014
B37: hnd | C37: 0.587797 | D37: 2002 | F37: 0.53672 | G37: 2013
B38: mex | C38: 0.512467 | D38: 2002 | F38: 0.4914 | G38: 2014
B39: nic | C39: 0.531416 | D39: 2001 | F39: 0.46564 | G39: 2014
... B45: ven | C45: 0.481547 | D45: 2002 | F45: 0.40829 | G45: 2012

Sheet Fig2
C2: Unfair 2002 | D2: Unfair 2013 | E2: Change
B3: Argentina | C3: 97.21519 | D3: 75.03944 | E3: 2
B4: Bolivia | C4: 88.04714 | D4: 63.43284 | E4: =+D4-C4 -> -24.6143
B5: Brazil | C5: 85.96491 | D5: 80.95238 | E5: =+D5-C5 -> -5.01253
B6: Chile | C6: 89.94845 | D6: 89.50821 | E6: =+D6-C6 -> -0.44024
B7: Colombia | C7: 89.11504 | D7: 85.3839 | E7: =+D7-C7 -> -3.73114
B8: Costa Rica | C8: 75 | D8: 84.13719 | E8: =+D8-C8 -> 9.13719
B9: Dominican Republic | C9: 74.32978 | D9: 72.61147 | E9: =+D9-C9 -> -1.71831
B10: Ecuador | C10: 87.58446 | D10: =+D22+5 -> 43.67841 | E10: =+D10-C10 -> -43.90605
B11: Guatemala | C11: 87.67876 | D11: 76.25388 | E11: =+D11-C11 -> -11.42488
B12: Honduras | C12: 82.48649 | D12: 87.05181 | E12: =+D12-C12 -> 4.56532
B13: Mexico | C13: 92 | D13: 79.96485 | E13: =+D13-C13 -> -12.03515
B14: Nicaragua | C14: 78.3903 | D14: 54.9497 | E14: =+D14-C14 -> -23.4406
B15: Panama | C15: 91.79488 | D15: 63.21353 | E15: =+D15-C15 -> -28.58135
B16: Peru | C16: 86.24014 | D16: 82.00537 | E16: =+D16-C16 -> -4.23477
B17: Paraguay | C17: 93.25464 | D17: 90.21622 | E17: =+D17-C17 -> -3.03842
B18: El Salvador | C18: 80.23122 | D18: 69.91288 | E18: =+D18-C18 -> -10.31834
B19: Uruguay | C19: 92.9127 | D19: 63.44464 | E19: =+D19-C19 -> -29.46806
B20: Venezuela | C20: 74.5325 | D20: 55.62231 | E20: =+D20-C20 -> -18.91019
B22: Real Ecuador 2013 | D22: 38.67841
B26: 45 line
B27: 30
B28: 100

Sheet Fig3
C2: ∆ Gini | D2: ∆ Unfairness
B3: Argentina | C3: =+'Fig1'!D3-'Fig1'!C3 -> -0.0789866 | D3: =+'Fig2'!D3-'Fig2'!C3 -> -22.17575
B4: Bolivia | C4: =+'Fig1'!D4-'Fig1'!C4 -> -0.12098066 | D4: =+'Fig2'!D4-'Fig2'!C4 -> -24.6143
B5: Brazil | C5: =+'Fig1'!D5-'Fig1'!C5 -> -0.05745938 | D5: =+'Fig2'!D5-'Fig2'!C5 -> -5.01253
B6: Chile | C6: =+'Fig1'!D6-'Fig1'!C6 -> -0.04254513 | D6: =+'Fig2'!D6-'Fig2'!C6 -> -0.44024
B7: Colombia | C7: =+'Fig1'!D7-'Fig1'!C7 -> -0.0476708 | D7: =+'Fig2'!D7-'Fig2'!C7 -> -3.73114
B8: Costa Rica | C8: =+'Fig1'!D8-'Fig1'!C8 -> 0.01079587 | D8: =+'Fig2'!D8-'Fig2'!C8 -> 9.13719
B9: Dominican Republic | C9: =+'Fig1'!D9-'Fig1'!C9 -> -0.03045234 | D9: =+'Fig2'!D9-'Fig2'!C9 -> -1.71831
B10: Ecuador | C10: =+'Fig1'!D10-'Fig1'!C10 -> -0.07702276 | D10: =+D22+15 -> -33.90605
B11: Guatemala | C11: =+'Fig1'!D11-'Fig1'!C11 -> -0.06232496 | D11: =+'Fig2'!D11-'Fig2'!C11 -> -11.42488
B12: Honduras | C12: =+'Fig1'!D12-'Fig1'!C12 -> -0.05108075 | D12: =+'Fig2'!D12-'Fig2'!C12 -> 4.56532
B13: Mexico | C13: =+'Fig1'!D13-'Fig1'!C13 -> -0.02106313 | D13: =+'Fig2'!D13-'Fig2'!C13 -> -12.03515
B14: Nicaragua | C14: =+'Fig1'!D14-'Fig1'!C14 -> -0.06577222 | D14: =+'Fig2'!D14-'Fig2'!C14 -> -23.4406
B15: Panama | C15: =+'Fig1'!D15-'Fig1'!C15 -> -0.00967341 | D15: =+'Fig2'!D15-'Fig2'!C15 -> -28.58135
B16: Peru | C16: =+'Fig1'!D16-'Fig1'!C16 -> -0.06469789 | D16: =+'Fig2'!D16-'Fig2'!C16 -> -4.23477
B17: Paraguay | C17: =+'Fig1'!D17-'Fig1'!C17 -> -0.09038839 | D17: =+'Fig2'!D17-'Fig2'!C17 -> -3.03842
B18: El Salvador | C18: =+'Fig1'!D18-'Fig1'!C18 -> -0.08022926 | D18: =+'Fig2'!D18-'Fig2'!C18 -> -10.31834
B19: Uruguay | C19: =+'Fig1'!D19-'Fig1'!C19 -> -0.04571893 | D19: =+'Fig2'!D19-'Fig2'!C19 -> -29.46806
B20: Venezuela | C20: =+'Fig1'!D20-'Fig1'!C20 -> -0.07325419 | D20: =+'Fig2'!D20-'Fig2'!C20 -> -18.91019
B22: Real Ecuador | D22: -48.90605

Sheet Fig4a
B2: Country | C2: Year | D2: Gini | E2: Unfair or Very Unfair | F2: Unfair | G2: Very Unfair | J2: Unfair or Very Unfair | R2: Country | S2: Year | T2: Gini | U2: Unfair or Very Unfair | V2: Unfair | W2: Very Unfair
B3: arg | C3: 2007 | D3: 0.47371702 | E3: 89.66282 | F3: 58.1863 | G3: 31.4765 | J3: Pooling all countries/years - does not include interpolated years | R3: arg | S3: 2015 | T3: 0.42666016 | U3: 78.53316 | V3: 59.2868 | W3: 19.2464
B4: arg | C4: 2009 | D4: 0.45273023 | E4: 95.54623 | F4: 51.276 | G4: 44.2702 | R4: bol | S4: 2015 | T4: 0.45777488 | U4: 52.99066 | V4: 42.8037 | W4: 10.1869
B5: arg | C5: 2010 | D5: 0.44495506 | E5: 87.6017 | F5: 53.6248 | G5: 33.9769 | R5: bra | S5: 2015 | T5: 0.51350794 | U5: 92.32653 | V5: 46.449 | W5: 45.8776
B6: arg | C6: 2011 | D6: 0.43572284 | E6: 83.6621 | F6: 61.652 | G6: 22.0101 | R6: chl | S6: 2015 | T6: 0.4765167 | U6: 94.94157 | V6: 48.4725 | W6: 46.4691
B7: arg | C7: 2013 | D7: 0.4228384 | E7: 75.03944 | F7: 55.7901 | G7: 19.2493 | R7: col | S7: 2015 | T7: 0.51069376 | U7: 85.58937 | V7: 50.4181 | W7: 35.1713
B8: arg | C8: 2015 | D8: 0.42666016 | E8: 78.53316 | F8: 59.2868 | G8: 19.2464 | R8: cri | S8: 2015 | T8: 0.48174398 | U8: 81.29497 | V8: 51.4902 | W8: 29.8047
B9: bol | C9: 1997 | D9: 0.58164428 | E9: 90.07732 | F9: 66.2371 | G9: 23.8402 | R9: dom | S9: 2015 | T9: 0.44880757 | U9: 74.40675 | V9: 52.0082 | W9: 22.3986
B10: bol | C10: 2001 | D10: 0.58876695 | E10: 91.39073 | F10: 57.1429 | G10: 34.2479 | R10: ecu | S10: 2015 | T10: 0.4654467 | U10: 46.21004 | V10: 33.516 | W10: 12.6941
B11: bol | C11: 2002 | D11: 0.6015836 | E11: 86.81402 | F11: 63.1664 | G11: 23.6476 | R11: gtm | S11: 2015 | T11: 0.48657004 | U11: 78.60542 | V11: 48.5862 | W11: 30.0193
B12: bol | C12: 2007 | D12: 0.55444921 | E12: 68.59862 | F12: 54.1523 | G12: 14.4464 | R12: hnd | S12: 2015 | T12: 0.50096061 | U12: 79.83633 | V12: 49.4728 | W12: 30.3635
B13: bol | C13: 2009 | D13: 0.49653071 | E13: 63.66843 | F13: 48.8536 | G13: 14.8148 | R13: mex | S13: 2015 | T13: 0.49140387 | U13: 82.42321 | V13: 47.7816 | W13: 34.6416
B14: bol | C14: 2011 | D14: 0.46260468 | E14: 78.10284 | F14: 65.5142 | G14: 12.5887 | R14: nic | S14: 2015 | T14: 0.46564378 | U14: 57.82407 | V14: 46.3445 | W14: 11.4796
B15: bol | C15: 2013 | D15: 0.48060334 | E15: 63.43284 | F15: 51.6791 | G15: 11.7537 | R15: pan | S15: 2015 | T15: 0.50981855 | U15: 62.10856 | V15: 43.1106 | W15: 18.9979
... B19: bra | C19: 2002 | D19: 0.58619826 | E19: 85.96491 | F19: 53.0444 | G19: 32.9205 | R19: ury | S19: 2015 | T19: 0.42006956 | U19: 65.70681 | V19: 56.1955 | W19: 9.51134
B20: bra | C20: 2007 | D20: 0.55233233 | E20: 86.27787 | F20: 53.1732 | G20: 33.1046
B21: bra | C21: 2009 | D21: 0.5387323 | E21: 83.37596 | F21: 58.3973 | G21: 24.9787
B22: bra | C22: 2011 | D22: 0.53094681 | E22: 85.13514 | F22: 58.4459 | G22: 26.6892 | J22: Pearson: | K22: All unfair | L22: Unfair | M22: Very Unfair
B23: bra | C23: 2013 | D23: 0.52873862 | E23: 80.95238 | F23: 47.8788 | G23: 33.0736 | J23: Pooled data | K23: =+PEARSON($D$3:$D$126,E3:E126) -> 0.38810868 | L23: =+PEARSON($D$3:$D$126,F3:F126) -> 0.096111309 | M23: =+PEARSON($D$3:$D$126,G3:G126) -> 0.35589343
B24: bra | C24: 2015 | D24: 0.51350794 | E24: 92.32653 | F24: 46.449 | G24: 45.8776 | J24: Only 2015 | K24: =+PEARSON($T$3:$T$19,U3:U19) -> 0.26050022 | L24: =+PEARSON($T$3:$T$19,V3:V19) -> -0.51132719 | M24: =+PEARSON($T$3:$T$19,W3:W19) -> 0.60133186
B25: chl | C25: 1997 | D25: 0.55522069 | E25: 88.39377 | F25: 53.937 | G25: 34.4568
B26: chl | C26: 2001 | D26: 0.52772009 | E26: 90.20447 | F26: 52.0365 | G26: 38.168
B27: chl | C27: 2002 | D27: 0.51489868 | E27: 90.86709 | F27: 60.4065 | G27: 30.4605
B28: chl | C28: 2007 | D28: 0.48217711 | E28: 90.23031 | F28: 45.3934 | G28: 44.8369 | J28: Spearman (stata) | K28: All unfair | L28: Unfair | M28: Very Unfair
B29: chl | C29: 2009 | D29: 0.48972761 | E29: 85.07493 | F29: 57.3888 | G29: 27.6861 | J29: Pooled data | K29: 0.4461 | L29: -0.4975 | M29: 0.6201
B30: chl | C30: 2011 | D30: 0.47617691 | E30: 94.08611 | F30: 45.0893 | G30: 48.9968 | J30: Only 2015 | K30: 0.3625 | L30: 0.0378 | M30: 0.4069
B31: chl | C31: 2013 | D31: 0.47263495 | E31: 89.50821 | F31: 36.0365 | G31: 53.4717
B32: chl | C32: 2015 | D32: 0.4765167 | E32: 94.94157 | F32: 48.4725 | G32: 46.4691
B33: col | C33: 2002 | D33: 0.58254918 | E33: 90.70968 | F33: 49.2116 | G33: 41.4981
B34: col | C34: 2007 | D34: 0.56042272 | E34: 81.37849 | F34: 52.5863 | G34: 28.7922
B35: col | C35: 2009 | D35: 0.5591804 | E35: 80.83848 | F35: 53.262 | G35: 27.5765
B36: col | C36: 2010 | D36: 0.55499444 | E36: 84.77905 | F36: 52.5424 | G36: 32.2367
B37: col | C37: 2011 | D37: 0.54175656 | E37: 87.82198 | F37: 58.6902 | G37: 29.1318
B38: col | C38: 2013 | D38: 0.5348782 | E38: 85.3839 | F38: 49.3001 | G38: 36.0838
B39: col | C39: 2015 | D39: 0.51069376 | E39: 85.58937 | F39: 50.4181 | G39: 35.1713
B40: cri | C40: 2010 | D40: 0.4809607 | E40: 73.08488 | F40: 53.2091 | G40: 19.8758
B41: cri | C41: 2011 | D41: 0.4859695 | E41: 75.4368 | F41: 50.9764 | G41: 24.4604
B42: cri | C42: 2013 | D42: 0.49175687 | E42: 84.13719 | F42: 47.6956 | G42: 36.4416
... B126: ven | C126: 2013 | D126: 0.40829281 | E126: 55.62231 | F126: 32.7897 | G126: 22.8326

Sheet Fig4b
B2: Year | C2: Very Unfair | D2: Unfair | E2: Unfair or Very Unfair | F2: Gini | H2: Changes | I2: 2002-2013 | J2: 2002-2015
B3: 1997 | C3: 28.757 | D3: 51.633 | E3: 80.39007 | F3: 0.54566875
H4: % Very Unfair | I4: =+C19/C8-1 -> -0.22506287 | J4: =+C21/C8-1 -> -0.21928955
H5: % Unfair | I5: =+D19/D8-1 -> -0.1167896 | J5: =+D21/D8-1 -> -0.079727447
B6: 2000 | H6: % Unfair or Very Unfair | I6: =+E19/E8-1 -> -0.15814982 | J6: =+E21/E8-1 -> -0.13304002
C7: 37.4349 | D7: 51.4348 | E7: 88.86971 | F7: 0.53624686 | H7: Gini | I7: =++F19/F8-1 -> -0.11333959 | J7: =++F21/F8-1 -> -0.13089216
C8: 33.0832 | D8: 53.5236 | E8: 86.6068 | F8: 0.53747916
H9: Elasticities | I9: 2002-2013 | J9: 2002-2015
B11: 2005 | H11: % Very Unfair | I11: =+I4/I$7 -> 1.9857392 | J11: =+J4/J$7 -> 1.6753451
H12: % Unfair | I12: =+I5/I$7 -> 1.0304396 | J12: =+J5/J$7 -> 0.60910787
C13: 27.5915 | D13: 50.1617 | E13: 77.75323 | F13: 0.50623315 | H13: % Unfair or Very Unfair | I13: =+I6/I$7 -> 1.3953625 | J13: =+J6/J$7 -> 1.0164093
C15: 24.4256 | D15: 53.4254 | E15: 77.85107 | F15: 0.48962709
B16: 2010 | C16: 24.7166 | D16: 53.232 | E16: 77.94858 | F16: 0.48464448 | I16: Pearson
C17: 24.4698 | D17: 54.9853 | E17: 79.45507 | F17: 0.48130264 | H17: Very unfair | I17: =+CORREL(C3:C21,F3:F21) -> 0.78821455
H18: Very + Unjust | I18: =+CORREL(E3:E21,F3:F21) -> 0.7973019
C19: 25.6374 | D19: 47.2726 | E19: 72.90995 | F19: 0.47656149 | H19: Unfair | I19: =+CORREL(D3:D21,F3:F21) -> 0.22124269
B21: 2015 | C21: 25.8284 | D21: 49.2563 | E21: 75.08463 | F21: 0.46712735

Sheet Fig5
B2: Year | C2: 18-24 | D2: 25-40 | E2: 41-64 | F2: 65+ | H2: Year | I2: Less than Primary | J2: Complete Primary | K2: Complete Secondary | L2: Complete Tertiary | N2: Year | O2: Females | P2: Males | R2: Year | S2: Employer | T2: Employee | U2: Self-Employed | V2: Unemployed
B3: 1997 | C3: 79.995687 | D3: 79.997159 | E3: 80.762373 | F3: 84.155243 | H3: 1997 | I3: 81.948172 | J3: 80.97505 | K3: 81.203034 | L3: 77.871672 | N3: 1997 | O3: 80.988666 | P3: 79.773456 | R3: 1997 | S3: 79.950643 | T3: 80.60123 | U3: 79.180559 | V3: 82.256941
B6: 2000 | H6: 2000 | N6: 2000 | R6: 2000
C7: 86.419657 | D7: 89.348585 | E7: 90.28158 | F7: 89.193925 | I7: 88.41132 | J7: 88.52854 | K7: 90.402915 | L7: 91.215445 | O7: 89.044744 | P7: 88.706262 | S7: 89.322752 | T7: 89.789025 | U7: 88.611321 | V7: 89.40409
C8: 83.822205 | D8: 86.856 | E8: 88.557156 | F8: 86.511873 | I8: 86.995269 | J8: 85.99965 | K8: 88.854792 | L8: 89.395166 | O8: 86.51565 | P8: 86.683241 | S8: 90.437394 | T8: 87.210194 | U8: 86.340307 | V8: 85.695163
B11: 2005 | H11: 2005 | N11: 2005 | R11: 2005
C14: 75.642607 | D14: 78.227129 | E14: 78.987487 | F14: 76.793696 | I14: 77.296756 | J14: 77.5846 | K14: 79.735294 | L14: 80.606464 | O14: 78.116998 | P14: 77.374378 | S14: 77.189726 | T14: 77.837673 | U14: 76.558554 | V14: 80.766167
C15: 75.606472 | D15: 78.149147 | E15: 78.628555 | F15: 78.659948 | I15: 76.659176 | J15: 78.354147 | K15: 77.786152 | L15: 80.252567 | O15: 78.517918 | P15: 77.163723 | S15: 77.236524 | T15: 77.589825 | U15: 77.656453 | V15: 78.972774
B16: 2010 | C16: 75.345437 | D16: 78.919239 | E16: 78.079687 | F16: 78.780118 | H16: 2010 | I16: 78.338312 | J16: 77.768524 | K16: 77.013451 | L16: 77.825896 | N16: 2010 | O16: 78.896541 | P16: 76.977158 | R16: 2010 | S16: 80.504812 | T16: 77.62999 | U16: 78.018067 | V16: 80.298821
C17: 76.004723 | D17: 80.14501 | E17: 80.564805 | F17: 79.880309 | I17: 80.809551 | J17: 78.490051 | K17: 78.744664 | L17: 80.874221 | O17: 80.604293 | P17: 78.258538 | S17: 78.237469 | T17: 78.902964 | U17: 78.922623 | V17: 80.676726
C19: 69.7001 | D19: 73.490541 | E19: 74.402009 | F19: 73.474798 | I19: 73.35465 | J19: 72.724764 | K19: 73.605366 | L19: 75.466129 | O19: 73.854362 | P19: 71.915323 | S19: 73.851133 | T19: 72.020234 | U19: 73.094014 | V19: 73.663313
B21: 2015 | C21: 73.113595 | D21: 74.614304 | E21: 77.348819 | F21: 75.369002 | H21: 2015 | I21: 76.0213 | J21: 74.643187 | K21: 74.673173 | L21: 76.811978 | N21: 2015 | O21: 75.87506 | P21: 74.269975 | R21: 2015 | S21: 74.390513 | T21: 74.377744 | U21: 76.248154 | V21: 75.08017
B23: Average | C23: =+AVERAGE(C3:C21) -> 77.294498 | D23: =+AVERAGE(D3:D21) -> 79.971902 | E23: =+AVERAGE(E3:E21) -> 80.84583 | F23: =+AVERAGE(F3:F21) -> 80.313212 | H23: Average | I23: =+AVERAGE(I3:I21) -> 79.981612 | J23: =+AVERAGE(J3:J21) -> 79.452057 | K23: =+AVERAGE(K3:K21) -> 80.224316 | L23: =+AVERAGE(L3:L21) -> 81.146615 | N23: Average | O23: =+AVERAGE(O3:O21) -> 80.268248 | P23: =+AVERAGE(P3:P21) -> 79.013562 | R23: Average | S23: =+AVERAGE(S3:S21) -> 80.124552 | T23: =+AVERAGE(T3:T21) -> 79.550987 | U23: =+AVERAGE(U3:U21) -> 79.403339 | V23: =+AVERAGE(V3:V21) -> 80.757129

Sheet Fig6
C2: Very Unfair | D2: Unfair | E2: Fair | F2: Very Fair
B3: 1997 | C3: 28.757023 | D3: 51.633045 | E3: 14.3243 | F3: 5.28562
B6: 2000
C7: 37.434868 | D7: 51.434837 | E7: 9.44698 | F7: 1.68331
C8: 33.083199 | D8: 53.523594 | E8: 11.2839 | F8: 2.10935
B11: 2005
C13: 27.591503 | D13: 50.161736 | E13: 17.9143 | F13: 4.33245
C15: 24.425638 | D15: 53.425438 | E15: 19.5347 | F15: 2.61418
B16: 2010 | C16: 24.716574 | D16: 53.232002 | E16: 19.4308 | F16: 2.62058
C17: 24.469807 | D17: 54.985264 | E17: 18.174 | F17: 2.3709
C19: 25.637388 | D19: 47.27256 | E19: 23.7114 | F19: 3.37865
B21: 2015 | C21: 25.828356 | D21: 49.256275 | E21: 22.6575 | F21: 2.2579

Sheet Fig7a
B2: Country | C2: Year | D2: Absolute Gini | E2: Unfair or Very Unfair | F2: Unfair | G2: Very Unfair | J2: Unfair or Very Unfair | R2: Country | S2: Year | T2: Absolute Gini | U2: Unfair or Very Unfair | V2: Unfair | W2: Very Unfair
B3: arg | C3: 2007 | D3: 97.203468 | E3: 89.66282 | F3: 58.1863 | G3: 31.4765 | J3: Pooling all countries/years - does not include interpolated years | R3: arg | S3: 2015 | T3: 93.101283 | U3: 78.53316 | V3: 59.2868 | W3: 19.2464
B4: arg | C4: 2009 | D4: 100.84667 | E4: 95.54623 | F4: 51.276 | G4: 44.2702 | R4: bol | S4: 2015 | T4: 106.2511 | U4: 52.99066 | V4: 42.8037 | W4: 10.1869
B5: arg | C5: 2010 | D5: 100.82579 | E5: 87.6017 | F5: 53.6248 | G5: 33.9769 | R5: bra | S5: 2015 | T5: 110.43559 | U5: 92.32653 | V5: 46.449 | W5: 45.8776
B6: arg | C6: 2011 | D6: 106.47556 | E6: 83.6621 | F6: 61.652 | G6: 22.0101 | R6: chl | S6: 2015 | T6: 123.73514 | U6: 94.94157 | V6: 48.4725 | W6: 46.4691
B7: arg | C7: 2013 | D7: 101.54722 | E7: 75.03944 | F7: 55.7901 | G7: 19.2493 | R7: col | S7: 2015 | T7: 104.01599 | U7: 85.58937 | V7: 50.4181 | W7: 35.1713
B8: arg | C8: 2015 | D8: 93.101283 | E8: 78.53316 | F8: 59.2868 | G8: 19.2464 | R8: cri | S8: 2015 | T8: 103.47058 | U8: 81.29497 | V8: 51.4902 | W8: 29.8047
B9: bol | C9: 1997 | D9: 99.547072 | E9: 90.07732 | F9: 66.2371 | G9: 23.8402 | R9: dom | S9: 2015 | T9: 105.34494 | U9: 74.40675 | V9: 52.0082 | W9: 22.3986
B10: bol | C10: 2001 | D10: 88.436081 | E10: 91.39073 | F10: 57.1429 | G10: 34.2479 | R10: ecu | S10: 2015 | T10: 107.54549 | U10: 46.21004 | V10: 33.516 | W10: 12.6941
B11: bol | C11: 2002 | D11: 89.836106 | E11: 86.81402 | F11: 63.1664 | G11: 23.6476 | R11: gtm | S11: 2015 | T11: 85.947304 | U11: 78.60542 | V11: 48.5862 | W11: 30.0193
B12: bol | C12: 2007 | D12: 99.471559 | E12: 68.59862 | F12: 54.1523 | G12: 14.4464 | R12: hnd | S12: 2015 | T12: 83.739397 | U12: 79.83633 | V12: 49.4728 | W12: 30.3635
B13: bol | C13: 2009 | D13: 98.062418 | E13: 63.66843 | F13: 48.8536 | G13: 14.8148 | R13: mex | S13: 2015 | T13: 99.529845 | U13: 82.42321 | V13: 47.7816 | W13: 34.6416
B14: bol | C14: 2011 | D14: 100.79937 | E14: 78.10284 | F14: 65.5142 | G14: 12.5887 | R14: nic | S14: 2015 | T14: 127.55759 | U14: 57.82407 | V14: 46.3445 | W14: 11.4796
B15: bol | C15: 2013 | D15: 117.5963 | E15: 63.43284 | F15: 51.6791 | G15: 11.7537 | R15: pan | S15: 2015 | T15: 114.05433 | U15: 62.10856 | V15: 43.1106 | W15: 18.9979
... B19: bra | C19: 2002 | D19: 88.953267 | E19: 85.96491 | F19: 53.0444 | G19: 32.9205 | R19: ury | S19: 2015 | T19: 110.99783 | U19: 65.70681 | V19: 56.1955 | W19: 9.51134
B20: bra | C20: 2007 | D20: 95.331945 | E20: 86.27787 | F20: 53.1732 | G20: 33.1046
B21: bra | C21: 2009 | D21: 100.76626 | E21: 83.37596 | F21: 58.3973 | G21: 24.9787
B22: bra | C22: 2011 | D22: 105.93178 | E22: 85.13514 | F22: 58.4459 | G22: 26.6892 | J22: Pearson: | K22: All unfair | L22: Unfair | M22: Very Unfair
B23: bra | C23: 2013 | D23: 119.03122 | E23: 80.95238 | F23: 47.8788 | G23: 33.0736 | J23: Pooled data | K23: =+PEARSON($D$3:$D$126,E3:E126) -> -0.20974711 | L23: =+PEARSON($D$3:$D$126,F3:F126) -> -0.17864989 | M23: =+PEARSON($D$3:$D$126,G3:G126) -> -0.10212758
B24: bra | C24: 2015 | D24: 110.43559 | E24: 92.32653 | F24: 46.449 | G24: 45.8776 | J24: Only 2015 | K24: =+PEARSON($T$3:$T$19,U3:U19) -> -0.1376528 | L24: =+PEARSON($T$3:$T$19,V3:V19) -> -0.23803805 | M24: =+PEARSON($T$3:$T$19,W3:W19) -> -0.025216308
B25: chl | C25: 1997 | D25: 110.38593 | E25: 88.39377 | F25: 53.937 | G25: 34.4568
B26: chl | C26: 2001 | D26: 89.578145 | E26: 90.20447 | F26: 52.0365 | G26: 38.168
B27: chl | C27: 2002 | D27: 85.647927 | E27: 90.86709 | F27: 60.4065 | G27: 30.4605
B28: chl | C28: 2007 | D28: 86.534575 | E28: 90.23031 | F28: 45.3934 | G28: 44.8369 | J28: Spearman (stata) | K28: All unfair | L28: Unfair | M28: Very Unfair
B29: chl | C29: 2009 | D29: 92.362655 | E29: 85.07493 | F29: 57.3888 | G29: 27.6861 | J29: Pooled data | K29: -0.1872 | L29: -0.1763 | M29: -0.1153
B30: chl | C30: 2011 | D30: 96.760579 | E30: 94.08611 | F30: 45.0893 | G30: 48.9968 | J30: Only 2015 | K30: -0.0637 | L30: -0.3529 | M30: -0.1471
B31: chl | C31: 2013 | D31: 114.99505 | E31: 89.50821 | F31: 36.0365 | G31: 53.4717
B32: chl | C32: 2015 | D32: 123.73514 | E32: 94.94157 | F32: 48.4725 | G32: 46.4691
B33: col | C33: 2002 | D33: 85.624815 | E33: 90.70968 | F33: 49.2116 | G33: 41.4981
B34: col | C34: 2007 | D34: 92.772654 | E34: 81.37849 | F34: 52.5863 | G34: 28.7922
B35: col | C35: 2009 | D35: 97.91785 | E35: 80.83848 | F35: 53.262 | G35: 27.5765
B36: col | C36: 2010 | D36: 103.26977 | E36: 84.77905 | F36: 52.5424 | G36: 32.2367
B37: col | C37: 2011 | D37: 106.2166 | E37: 87.82198 | F37: 58.6902 | G37: 29.1318
B38: col | C38: 2013 | D38: 110.1823 | E38: 85.3839 | F38: 49.3001 | G38: 36.0838
B39: col | C39: 2015 | D39: 104.01599 | E39: 85.58937 | F39: 50.4181 | G39: 35.1713
B40: cri | C40: 2010 | D40: 93.91592 | E40: 73.08488 | F40: 53.2091 | G40: 19.8758
B41: cri | C41: 2011 | D41: 97.070368 | E41: 75.4368 | F41: 50.9764 | G41: 24.4604
B42: cri | C42: 2013 | D42: 105.54314 | E42: 84.13719 | F42: 47.6956 | G42: 36.4416
... B126: ven | C126: 2013 | D126: 116.05934 | E126: 55.62231 | F126: 32.7897 | G126: 22.8326

Sheet Fig7b
B2: Year | C2: Very Unfair | D2: Unfair | E2: Unfair or Very Unfair | F2: Absolute Gini
B3: 1997 | C3: 28.874247 | D3: 51.551041 | E3: 80.425285 | F3: 89.39867
B6: 2000
C7: 37.615295 | D7: 51.500446 | E7: 89.115746 | F7: 92.710798
C8: 33.000435 | D8: 53.611145 | E8: 86.61158 | F8: 89.94012
B11: 2005
C13: 27.63191 | D13: 50.16441 | E13: 77.796318 | F13: 97.980138
C15: 24.49325 | D15: 53.453693 | E15: 77.946945 | F15: 97.804201
B16: 2010 | C16: 24.621641 | D16: 53.396576 | E16: 78.018219 | F16: 98.345262
C17: 24.189562 | D17: 55.221973 | E17: 79.411537 | F17: 101.32556
C19: 25.101715 | D19: 47.690685 | E19: 72.792404 | F19: 106.61431
B21: 2015 | C21: 25.509338 | D21: 49.247292 | E21: 74.75663 | F21: 107.00045
D24: Pearson
C25: Very unjust | D25: =+CORREL(C3:C21,F3:F21) -> -0.66713804
C26: Very + Unjust | D26: =+CORREL(E3:E21,F3:F21) -> -0.80359085
C27: Unjust | D27: =+CORREL(D3:D21,F3:F21) -> -0.46309242

Sheet Fig8
C2: Unfair or Very Unfair
B3: 2002 | C3: 86.86861 | H3: 2002 | I3: 2013 | J3: Change 2002-13 | L3: Demographics/Gini
B4: 2013 | C4: 73.01 | H4: =+C3 -> 86.86861 | I4: =+C4 -> 73.01 | J4: =+C4 -> 73.01 | L4: =+C4 -> 73.01
B5: Change | C5: =+C3-C4 -> 13.85861 | I5: =+C5 -> 13.85861 | J5: =+C6 -> 9.33605 | L5: =+C9 -> 4.52256
B6: Explained (endowments) | C6: 9.33605 | D6: =+C6/C5 -> 0.67366424 | J6: =+C9 -> 4.52256 | L6: =+D7 -> -0.18087
B7: Demographics | D7: =+C6-D8 -> -0.18087 | L7: =+D8 -> 9.51692
B8: Gini | D8: 9.51692
B9: Unexplained (coefficients + interaction) | C9: =+C5-C6 -> 4.52256 | D9: =+C9/C5 -> 0.32633576
B17: time | C17: value | D17: comp
B18: 1 | C18: 86.9 | D18: ini
B19: 2 | C19: 73 | D19: fin
B20: 2 | C20: =+C18-C19 -> 13.9 | D20: z1
B21: 3 | C21: 73 | D21: a1
B22: 3 | C22: 9.3 | D22: explained
B23: 3 | C23: 4.5 | D23: unexplained
B24: 4 | C24: 86.9 | D24: a1

Sheet Fig9
C2: Very Unfair | D2: Unfair | E2: Work | F2: Democracy | G2: Education | H2: Nature | K2: Work | L2: Democracy | M2: Education | N2: Nature
B3: arg | C3: 19.2464 | D3: 78.53316 | E3: 5.61076 | F3: 6.175121 | G3: 6.507479 | H3: 5.662633 | J3: Very Unfair | K3: =+CORREL($C$3:$C$20,E3:E20) -> 0.2545174 | L3: =+CORREL($C$3:$C$20,F3:F20) -> 0.054840898 | M3: =+CORREL($C$3:$C$20,G3:G20) -> 0.28078351 | N3: =+CORREL($C$3:$C$20,H3:H20) -> 0.41695222
B4: bol | C4: 10.1869 | D4: 52.99066 | E4: 6.845411 | F4: 6.713178 | G4: 7.519084 | H4: 6.322266 | J4: Unfair | K4: =+CORREL($D$3:$D$20,E3:E20) -> 0.28126638 | L4: =+CORREL($D$3:$D$20,F3:F20) -> 0.17815941 | M4: =+CORREL($D$3:$D$20,G3:G20) -> 0.35311872 | N4: =+CORREL($D$3:$D$20,H3:H20) -> 0.49571796
B5: bra | C5: 45.8776 | D5: 92.32653 | E5: 6.50176 | F5: 6.058076 | G5: 7.156059 | H5: 5.908438
B6: chl | C6: 46.4691 | D6: 94.94157 | E6: 6.914412 | F6: 6.194508 | G6: 7.221956 | H6: 6.597945
B7: col | C7: 35.1713 | D7: 85.58937 | E7: 7.217413 | F7: 6.593579 | G7: 8.003613 | H7: 6.933737
B8: cri | C8: 29.8047 | D8: 81.29497 | E8: 6.355879 | F8: 6.926931 | G8: 7.216805 | H8: 6.430963
B9: dom | C9: 22.3986 | D9: 74.40675 | E9: 7.6213 | F9: 7.524772 | G9: 8.317804 | H9: 6.174728
B10: ecu | C10: 12.6941 | D10: 46.21004 | E10: 4.641527 | F10: 4.475746 | G10: 5.089386 | H10: 4.266355
B11: gtm | C11: 30.0193 | D11: 78.60542 | E11: 6.208662 | F11: 6.011352 | G11: 7.61014 | H11: 6.084396
B12: hnd | C12: 30.3635 | D12: 79.83633 | E12: 6.960906 | F12: 6.361162 | G12: 7.936144 | H12: 6.209133
B13: mex | C13: 34.6416 | D13: 82.42321 | E13: 6.591731 | F13: 6.477612 | G13: 7.333045 | H13: 6.133451
B14: nic | C14: 11.4796 | D14: 57.82407 | E14: 7.236559 | F14: 6.87618 | G14: 7.369817 | H14: 6.247028
B15: pan | C15: 18.9979 | D15: 62.10856 | E15: 6.429936 | F15: 6.382227 | G15: 7.027455 | H15: 5.843348
B16: per | C16: 21.0385 | D16: 82.27395 | E16: 6.195077 | F16: 6.217391 | G16: 6.712329 | H16: 6.002768
... B20: ven | C20: 33.448 | D20: 74.03268 | E20: 5.32463 | F20: 5.847295 | G20: 5.741739 | H20: 5.063533
B23: Very Unfair | M23: Unfair

Sheet Table1
B2: Correlation with… | C2: Pooling all the data | G2: Averaging indicators | K2: Averaging correlations
C3: U. or V.U. | D3: V.U. | E3: U. | G3: U. or V.U. | H3: V.U. | I3: U. | K3: U. or V.U. | L3: V.U. | M3: U.
C4: (1) | D4: (2) | E4: (3) | G4: (4) | H4: (5) | I4: (6) | K4: (7) | L4: (8) | M4: (9)
B5: Gini coefficient | C5: 0.38810866 | D5: 0.35589334 | E5: 0.09611125 | G5: 0.8413604 | H5: 0.82218541 | I5: 0.2511908 | K5: 0.3915612 | L5: 0.27793983 | M5: 0.14657072
C6: (0.07) | D6: (0.07) | E6: (0.09) | G6: (0.10) | H6: (0.16) | I6: (0.35) | K6: (0.07) | L6: (0.07) | M6: (0.09)
B7: Theil index, GE(1) | C7: 0.38533682 | D7: 0.38459631 | E7: 0.05153855 | G7: 0.84988395 | H7: 0.82283023 | I7: 0.26793176 | K7: 0.3258576 | L7: 0.19587609 | M7: 0.18094955
C8: (0.07) | D8: (0.07) | E8: (0.09) | G8: (0.09) | H8: (0.16) | I8: (0.35) | K8: (0.07) | L8: (0.07) | M8: (0.09)
B9: Atkinson, A(0.5) | C9: 0.38286939 | D9: 0.35060789 | E9: 0.09548952 | G9: 0.84291283 | H9: 0.8227743 | I9: 0.25336894 | K9: 0.37413652 | L9: 0.25562001 | M9: 0.14988997
C10: (0.07) | D10: (0.07) | E10: (0.09) | G10: (0.10) | H10: (0.16) | I10: (0.35) | K10: (0.07) | L10: (0.07) | M10: (0.09)
B11: Atkinson, A(1) | C11: 0.35827509 | D11: 0.30070954 | E11: 0.12780847 | G11: 0.83698362 | H11: 0.81862547 | I11: 0.24855932 | K11: 0.3803892 | L11: 0.27993894 | M11: 0.12715948
C12: (0.07) | D12: (0.08) | E12: (0.09) | G12: (0.10) | H12: (0.16) | I12: (0.34) | K12: (0.07) | L12: (0.08) | M12: (0.09)
B13: Mean log deviation, GE(0) | C13: 0.3520381 | D13: 0.28817439 | E13: 0.1358375 | G13: 0.83719288 | H13: 0.81801193 | I13: 0.250133 | K13: 0.3799732 | L13: 0.28152541 | M13: 0.1250616
C14: (0.07) | D14: (0.08) | E14: (0.09) | G14: (0.10) | H14: (0.16) | I14: (0.34) | K14: (0.07) | L14: (0.08) | M14: (0.09)
B15: Coefficient Variation | C15: 0.32955287 | D15: 0.36321207 | E15: -0.00408973 | G15: 0.77963404 | H15: 0.78343592 | I15: 0.19291392 | K15: 0.18410751 | L15: 0.19662595 | M15: 0.097643889
C16: (0.08) | D16: (0.08) | E16: (0.09) | G16: (0.13) | H16: (0.16) | I16: (0.36) | K16: (0.08) | L16: (0.08) | M16: (0.09)
B17: Ratio 75/25 | C17: 0.29344055 | D17: 0.14715251 | E17: 0.24393139 | G17: 0.80430503 | H17: 0.77615309 | I17: 0.25827178 | K17: 0.35801552 | L17: 0.29120726 | M17: 0.12068013
C18: (0.07) | D18: (0.09) | E18: (0.08) | G18: (0.11) | H18: (0.17) | I18: (0.33) | K18: (0.07) | L18: (0.09) | M18: (0.08)
B19: Generalized entropy, GE(2) | C19: 0.29202814 | D19: 0.34977175 | E19: -0.04283618 | G19: 0.79842088 | H19: 0.71990381 | I19: 0.34980667 | K19: 0.17752865 | L19: 0.094932473 | M19: 0.19226702
C20: (0.05) | D20: (0.08) | E20: (0.08) | G20: (0.11) | H20: (0.18) | I20: (0.34) | K20: (0.05) | L20: (0.08) | M20: (0.08)
B21: Ratio 90/10 | C21: 0.23151631 | D21: 0.10325586 | E21: 0.2104947 | G21: 0.81185481 | H21: 0.78842644 | I21: 0.25148159 | K21: 0.30272834 | L21: 0.29751996 | M21: 0.071678011
C22: (0.07) | D22: (0.08) | E22: (0.08) | G22: (0.11) | H22: (0.17) | I22: (0.32) | K22: (0.07) | L22: (0.08) | M22: (0.08)
B23: Variance | C23: -0.08321199 | D23: -0.00516633 | E23: -0.12052778 | G23: -0.24735825 | H23: 0.10016945 | I23: -0.70545361 | K23: -0.059462841 | L23: 0.040251903 | M23: -0.11892652
C24: (0.07) | D24: (0.08) | E24: (0.08) | G24: (0.39) | H24: (0.43) | I24: (0.14) | K24: (0.07) | L24: (0.08) | M24: (0.08)
B25: Absolute Gini | C25: -0.20974709 | D25: -0.10212758 | E25: -0.17864959 | G25: -0.7118706 | H25: -0.46338113 | I25: -0.64161614 | K25: -0.1787352 | L25: -0.10050412 | M25: -0.21770697
C26: (0.09) | D26: (0.10) | E26: (0.08) | G26: (0.23) | H26: (0.26) | I26: (0.31) | K26: (0.09) | L26: (0.10) | M26: (0.08)
B27: Kolm, K(1) | C27: -0.30705613 | D27: -0.18093096 | E27: -0.21739496 | G27: -0.79594697 | H27: -0.63816332 | I27: -0.4956087 | K27: -0.22281383 | L27: -0.15634589 | M27: -0.2184079
C28: (0.09) | D28: (0.10) | E28: (0.08) | G28: (0.12) | H28: (0.18) | I28: (0.37) | K28: (0.09) | L28: (0.10) | M28: (0.08)

Sheet TableA1
A1: Category | B1: Variable | C1: Mean | D1: Obs | E1: Std_Dev
A2: Access to services | B2: Access to a sewage (%) | C2: 69.731972 | D2: 164743 | E2: 0.4594194 | G2: Row Labels | H2: Mean | I2: Standard Deviation | J2: Observations | L2: Variables | M2: Mean | N2: Standard Dev. | O2: Observations
A3: Access to services | B3: Access to running water (%) | C3: 87.674377 | D3: 146354 | E3: 0.32873219 | G3: Socio-demographic | L3: Sociodemographic
A4: Asset ownership | B4: Car (%) | C4: 27.285158 | D4: 164521 | E4: 0.44542655 | G4: Age | H4: 39.488846 | I4: 16.175087 | J4: 167420 | L4: Age | M4: 39.488846 | N4: 16.175087 | O4: 167420
A5: Asset ownership | B5: Computer (%) | C5: 29.632151 | D5: 164719 | E5: 0.45663589 | G5: Male (%) | H5: 49.080864 | I5: 0.499917 | J5: 167436 | L5: Male (%) | M5: 49.080864 | N5: 0.499917 | O5: 167436
A6: Asset ownership | B6: Fridge (%) | C6: 79.216911 | D6: 146686 | E6: 0.4057565 | G6: Catholic religion (%) | H6: 70.700577 | I6: 0.45513722 | J6: 165329 | L6: Catholic religion (%) | M6: 70.700577 | N6: 0.45513722 | O6: 165329
A7: Asset ownership | B7: Homeowner (%) | C7: 73.650879 | D7: 165650 | E7: 0.44052783 | G7: Married or civil union (%) | H7: 57.301521 | I7: 0.49464154 | J7: 166121 | L7: Married or civil union (%) | M7: 57.301521 | N7: 0.49464154 | O7: 166121
A8: Asset ownership | B8: Landline (%) | C8: 45.142822 | D8: 165108 | E8: 0.49763671 | G8: City > 1 Mill. Inhab. (%) | H8: 50.433247 | I8: 0.49998289 | J8: 150224 | L8: City > 1 Mill. Inhab. (%) | M8: 50.433247 | N8: 0.49998289 | O8: 150224
A9: Asset ownership | B9: Mobile (%) | C9: 76.485176 | D9: 114297 | E9: 0.42409328 | G9: Education and Labor market | L9: Education and Labor market
A10: Asset ownership | B10: Washing machine (%) | C10: 51.721161 | D10: 165195 | E10: 0.4997052 | G10: Literate (%) | H10: 89.953857 | I10: 0.30061513 | J10: 165925 | L10: Literate (%) | M10: 89.953857 | N10: 0.30061513 | O10: 165925
A11: Education and Labor market | B11: Economically active (%) | C11: 64.068756 | D11: 167091 | E11: 0.47980037 | G11: Secondary education or more (%) | H11: 32.383068 | I11: 0.46793768 | J11: 165925 | L11: Secondary education or more (%) | M11: 32.383068 | N11: 0.46793768 | O11: 165925
A12: Education and Labor market | B12: Literate (%) | C12: 89.953857 | D12: 165925 | E12: 0.30061513 | G12: Parents with secondary education (%) | H12: 16.76866 | I12: 0.37358916 | J12: 132792 | L12: Parents with secondary education (%) | M12: 16.76866 | N12: 0.37358916 | O12: 132792
A13: Education and Labor market | B13: Parents with secondary education (%) | C13: 16.76866 | D13: 132792 | E13: 0.37358916 | G13: Economically active (%) | H13: 64.068756 | I13: 0.47980037 | J13: 167091 | L13: Economically active (%) | M13: 64.068756 | N13: 0.47980037 | O13: 167091
A14: Education and Labor market | B14: Secondary education or more (%) | C14: 32.383068 | D14: 165925 | E14: 0.46793768 | G14: Unemployed (% Labor Force) | H14: 9.9489355 | I14: 0.29931933 | J14: 167091 | L14: Unemployed (% Labor Force) | M14: 9.9489355 | N14: 0.29931933 | O14: 167091
A15: Education and Labor market | B15: Unemployed (% Labor Force) | C15: 9.9489355 | D15: 167091 | E15: 0.29931933 | G15: Access to services | L15: Access to services
A16: Socio-demographic | B16: Age | C16: 39.488846 | D16: 167420 | E16: 16.175087 | G16: Access to a sewage (%) | H16: 69.731972 | I16: 0.4594194 | J16: 164743 | L16: Access to a sewage (%) | M16: 69.731972 | N16: 0.4594194 | O16: 164743
A17: Socio-demographic | B17: Catholic religion (%) | C17: 70.700577 | D17: 165329 | E17: 0.45513722 | G17: Access to running water (%) | H17: 87.674377 | I17: 0.32873219 | J17: 146354 | L17: Access to running water (%) | M17: 87.674377 | N17: 0.32873219 | O17: 146354
A18: Socio-demographic | B18: City > 1 Mill. Inhab. (%) | C18: 50.433247 | D18: 150224 | E18: 0.49998289 | G18: Asset ownership | L18: Asset ownership
A19: Socio-demographic | B19: Male (%) | C19: 49.080864 | D19: 167436 | E19: 0.499917 | G19: Car (%) | H19: 27.285158 | I19: 0.44542655 | J19: 164521 | L19: Car (%) | M19: 27.285158 | N19: 0.44542655 | O19: 164521
A20: Socio-demographic | B20: Married or civil union (%) | C20: 57.301521 | D20: 166121 | E20: 0.49464154 | G20: Computer (%) | H20: 29.632151 | I20: 0.45663589 | J20: 164719 | L20: Computer (%) | M20: 29.632151 | N20: 0.45663589 | O20: 164719
G21: Fridge (%) | H21: 79.216911 | I21: 0.4057565 | J21: 146686 | L21: Fridge (%) | M21: 79.216911 | N21: 0.4057565 | O21: 146686
G22: Homeowner (%) | H22: 73.650879 | I22: 0.44052783 | J22: 165650 | L22: Homeowner (%) | M22: 73.650879 | N22: 0.44052783 | O22: 165650
G23: Mobile (%) | H23: 76.485176 | I23: 0.42409328 | J23: 114297 | L23: Mobile (%) | M23: 76.485176 | N23: 0.42409328 | O23: 114297
G24: Washing machine (%) | H24: 51.721161 | I24: 0.4997052 | J24: 165195 | L24: Washing machine (%) | M24: 51.721161 | N24: 0.4997052 | O24: 165195
G25: Landline (%) | H25: 45.142822 | I25: 0.49763671 | J25: 165108 | L25: Landline (%) | M25: 45.142822 | N25: 0.49763671 | O25: 165108

Sheet TableA2
A1: Year | B1: Category | C1: Level | D1: Class | E1: Percent | H1: Year | I1: all
A2: 1997 | B2: All | C2: All | D2: Very unfair | E2: 29.142689
A3: 1997 | B3: Education level | C3: Less than Primary | D3: Very unfair | E3: 29.884736 | H3: Sum of Percent | O3: Category | P3: Perception of about income distribution
A4: 1997 | B4: Education level | C4: Complete Primary | D4: Very unfair | E4: 30.058012 | I4: Very unfair | J4: Unfair | K4: Fair | L4: Very fair | M4: Total | P4: Very unfair | Q4: Unfair | R4: Fair | S4: Very fair | T4: Total
A5: 1997 | B5: Education level | C5: Complete Secondary | D5: Very unfair | E5: 28.006653 | H5: All | O5: All | P5: 27.999671 | Q5: 51.634308 | R5: 17.455631 | S5: 2.9103903 | T5: 100
A6: 1997 | B6: Education level | C6: Complete Tertiary | D6: Very unfair | E6: 27.876406 | H6: All | I6: 27.999671 | J6: 51.634308 | K6: 17.455631 | L6: 2.9103903 | M6: 100 | O6: Gender
A7: 1997 | B7: Age group | C7: 15-24 | D7: Very unfair | E7: 27.7637 | H7: Gender | O7: Female | P7: 28.138996 | Q7: 52.213149 | R7: 16.842708 | S7: 2.8051472 | T7: 100
A8: 1997 | B8: Age group | C8: 25-40 | D8: Very unfair | E8: 27.477146 | H8: Female | I8: 28.138996 | J8: 52.213149 | K8: 16.842708 | L8: 2.8051472 | M8: 100 | O8: Male | P8: 27.855128 | Q8: 51.033787 | R8: 18.09151 | S8: 3.0195752 | T8: 100
A9: 1997 | B9: Age group | C9: 41-64 | D9: Very unfair | E9: 31.807994 | H9: Male | I9: 27.855128 | J9: 51.033787 | K9: 18.09151 | L9: 3.0195752 | M9: 100 | O9: Age group
A10: 1997 | B10: Age group | C10: 65+ | D10: Very unfair | E10: 32.054369 | H10: Age group | O10: 15-24 | P10: 25.257491 | Q10: 52.015379 | R10: 19.642796 | S10: 3.0843346 | T10: 100
A11: 1997 | B11: Gender | C11: Female | D11: Very unfair | E11: 30.198123 | H11: 15-24 | I11: 25.257491 | J11: 52.015379 | K11: 19.642796 | L11: 3.0843346 | M11: 100 | O11: 25-40 | P11: 28.33838 | Q11: 51.349399 | R11: 17.287895 | S11: 3.0243258 | T11: 100
A12: 1997 | B12: Gender | C12: Male | D12: Very unfair | E12: 28.045609 | H12: 25-40 | I12: 28.33838 | J12: 51.349399 | K12: 17.287895 | L12: 3.0243258 | M12: 100 | O12: 41-64 | P12: 29.181638 | Q12: 51.73338 | R12: 16.307041 | S12: 2.777942 | T12: 100
A13: 1997 | B13: Civil Status | C13: Not married | D13: Very unfair | E13: 29.627672 | H13: 41-64 | I13: 29.181638 | J13: 51.73338 | K13: 16.307041 | L13: 2.777942 | M13: 100 | O13: 65+ | P13: 28.785714 | Q13: 51.600661 | R13: 17.133383 | S13: 2.4802423 | T13: 100
A14: 1997 | B14: Civil Status | C14: Married | D14: Very unfair | E14: 28.639406 | H14: 65+ | I14: 28.785714 | J14: 51.600661 | K14: 17.133383 | L14: 2.4802423 | M14: 100 | O14: Civil Status
A15: 1997 | B15: Religion | C15: Not catholic | D15: Very unfair | E15: 29.726872 | H15: Civil Status | O15: Married | P15: 28.153396 | Q15: 51.931417 | R15: 17.140133 | S15: 2.7750537 | T15: 100
A16: 1997 | B16: Religion | C16: Catholic | D16: Very unfair | E16: 29.047379 | H16: Married | I16: 28.153396 | J16: 51.931417 | K16: 17.140133 | L16: 2.7750537 | M16: 100 | O16: Not married | P16: 27.732327 | Q16: 51.334649 | R16: 17.871945 | S16: 3.0610786 | T16: 100
A17: 1997 | B17: Type of employment | C17: Employer | D17: Very unfair | E17: 29.502255 | H17: Not married | I17: 27.732327 | J17: 51.334649 | K17: 17.871945 | L17: 3.0610786 | M17: 100 | O17: Religion
A18: 1997 | B18: Type of employment | C18: Employee | D18: Very unfair | E18: 28.432231 | H18: Religion | O18: Catholic | P18: 28.151103 | Q18: 51.743653 | R18: 17.214878 | S18: 2.8903658 | T18: 100
A19: 1997 | B19: Type of employment | C19: Self-employed | D19: Very unfair | E19: 28.488324 | H19: Catholic | I19: 28.151103 | J19: 51.743653 | K19: 17.214878 | L19: 2.8903658 | M19: 100 | O19: Not catholic | P19: 27.53534 | Q19: 51.468244 | R19: 18.079992 | S19: 2.9164243 | T19: 100
A20: 1997 | B20: Type of employment | C20: Unemployed | D20: Very unfair | E20: 30.389675 | H20: Not catholic | I20: 27.53534 | J20: 51.468244 | K20: 18.079992 | L20: 2.9164243 | M20: 100 | O20: Education level
A21: 1997 | B21: City size | C21: Under 100,000 | D21: Very unfair | H21: Education level | O21: Less than Primary | P21: 28.743028 | Q21: 50.915665 | R21: 17.338661 | S21: 3.0026468 | T21: 100
A22: 1997 | B22: City size | C22: 100,000 to 1,000,000 | D22: Very unfair | H22: Complete Primary | I22: 27.575163 | J22: 51.584857 | K22: 17.865565 | L22: 2.9744145 | M22: 100 | O22: Complete Primary | P22: 27.575163 | Q22: 51.584857 | R22: 17.865565 | S22: 2.9744145 | T22: 100
A23: 1997 | B23: City size | C23: More than 1,000,000 | D23: Very unfair | H23: Complete Secondary | I23: 27.620497 | J23: 52.050793 | K23: 17.71419 | L23: 2.6145195 | M23: 100 | O23: Complete Secondary | P23: 27.620497 | Q23: 52.050793 | R23: 17.71419 | S23: 2.6145195 | T23: 100
A24: 1997 | B24: Country | C24: Argentina | D24: Very unfair | E24: 54.739539 | H24: Complete Tertiary | I24: 28.689698 | J24: 52.899415 | K24: 15.645987 | L24: 2.7648992 | M24: 100 | O24: Complete Tertiary | P24: 28.689698 | Q24: 52.899415 | R24: 15.645987 | S24: 2.7648992 | T24: 100
A25: 1997 | B25: Country | C25: Bolivia | D25: Very unfair | E25: 23.840206 | H25: Less than Primary | I25: 28.743028 | J25: 50.915665 | K25: 17.338661 | L25: 3.0026468 | M25: 100 | O25: Type of employment
A26: 1997 | B26: Country | C26: Brazil | D26: Very unfair | E26: 38.52459 | H26: Type of employment | O26: Employee | P26: 28.111582 | Q26: 51.47569 | R26: 17.464852 | S26: 2.9478764 | T26: 100
A27: 1997 | B27: Country | C27: Chile | D27: Very unfair | E27: 34.456807 | H27: Employee | I27: 28.111582 | J27: 51.47569 | K27: 17.464852 | L27: 2.9478764 | M27: 100 | O27: Employer | P27: 27.105547 | Q27: 52.523158 | R27: 17.545831 | S27: 2.8254632 | T27: 100
A28: 1997 | B28: Country | C28: Colombia | D28: Very unfair | E28: 32.517524 | H28: Employer | I28: 27.105547 | J28: 52.523158 | K28: 17.545831 | L28: 2.8254632 | M28: 100 | O28: Self-employed | P28: 27.859621 | Q28: 51.068111 | R28: 17.891306 | S28: 3.1809625 | T28: 100
A29: 1997 | B29: Country | C29: Costa Rica | D29: Very unfair | E29: 15.314402 | H29: Self-employed | I29: 27.859621 | J29: 51.068111 | K29: 17.891306 | L29: 3.1809625 | M29: 100 | O29: Unemployed | P29: 30.610005 | Q29: 51.525346 | R29: 14.949833 | S29: 2.9148168 | T29: 100
A30: 1997 | B30: Country | C30: Dominican Rep. | D30: Very unfair | H30: Unemployed | I30: 30.610005 | J30: 51.525346 | K30: 14.949833 | L30: 2.9148168 | M30: 100
A31: 1997 | B31: Country | C31: Ecuador | D31: Very unfair | E31: 32.508834 | H31: City size
A32: 1997 | B32: Country | C32: Guatemala | D32: Very unfair | E32: 24.757804 | H32: 100,000 to 1,000,000 | I32: 26.227543 | J32: 51.748459 | K32: 19.143678 | L32: 2.8803201 | M32: 100
A33: 1997 | B33: Country | C33: Honduras | D33: Very unfair | E33: 15.686275 | H33: More than 1,000,000 | I33: 29.363797 | J33: 51.21283 | K33: 16.792816 | L33: 2.6305565 | M33: 100
A34: 1997 | B34: Country | C34: Mexico | D34: Very unfair | E34: 32.033426 | H34: Under 100,000 | I34: 26.510548 | J34: 52.653527 | K34: 18.463691 | L34: 2.3722331 | M34: 100
A35: 1997 | B35: Country | C35: Nicaragua | D35: Very unfair | E35: 19.28934 | H35: Country
A36: 1997 | B36: Country | C36: Panama | D36: Very unfair | E36: 20.620621 | H36: Argentina | I36: 38.378035 | J36: 50.660419 | K36: 10.135151 | L36: 0.82639481 | M36: 100
A37: 1997 | B37: Country | C37: Peru | D37: Very unfair | E37: 28.795299 | H37: Bolivia | I37: 17.768688 | J37: 55.871419 | K37: 23.881611 | L37: 2.4782814 | M37: 100
A38: 1997 | B38: Country | C38: Paraguay | D38: Very unfair | E38: 35.670608 | H38: Brazil | I38: 31.814982 | J38: 53.745601 | K38: 12.941176 | L38: 1.4982403 | M38: 100
A39: 1997 | B39: Country | C39: El Salvador | D39: Very unfair | E39: 16.565657 | H39: Chile | I39: 40.195058 | J39: 49.935273 | K39: 8.423197 | L39: 1.4464719 | M39: 100
A40: 1997 | B40: Country | C40: Uruguay | D40: Very unfair | E40: 26.48553 | H40: Colombia | I40: 35.132966 | J40: 51.206936 | K40: 11.398651 | L40: 2.2614466 | M40: 100
...

Sheet TableA3
A1: Year | B1: Category | C1: Level | D1: Class | E1: Percent | H1: Year | I1: all
A2: 1997 | B2: All | C2: All | D2: Very unfair | E2: 29.142689
A3: 1997 | B3: Education level | C3: Less than Primary | D3: Very unfair | E3: 29.884736 | H3: Sum of Percent | O3: Category | P3: Perception of about income distribution
A4: 1997 | B4: Education level | C4: Complete Primary | D4: Very unfair | E4: 30.058012 | I4: Very unfair | J4: Unfair | K4: Fair | L4: Very fair | M4: Total | P4: Very unfair | Q4: Unfair | R4: Fair | S4: Very fair | T4: Total
A5: 1997 | B5: Education level | C5: Complete Secondary | D5: Very unfair | E5: 28.006653 | H5: All | O5: City size
A6: 1997 | B6: Education level | C6: Complete Tertiary | D6: Very unfair | E6: 27.876406 | H6: All | I6: 27.999671 | J6: 51.634308 | K6: 17.455631 | L6: 2.9103903 | M6: 100 | O6: Under 100,000 | P6: 26.510548 | Q6: 52.653527 | R6: 18.463691 | S6: 2.3722331 | T6: 100
A7: 1997 | B7: Age group | C7: 15-24 | D7: Very unfair | E7: 27.7637 | H7: Gender | O7: 100,000 to 1,000,000 | P7: 26.227543 | Q7: 51.748459 | R7: 19.143678 | S7: 2.8803201 | T7: 100
A8: 1997 | B8: Age group | C8: 25-40 | D8: Very unfair | E8: 27.477146 | H8: Female | I8: 28.138996 | J8: 52.213149 | K8: 16.842708 | L8: 2.8051472 | M8: 100 | O8: More than 1,000,000 | P8: 29.363797 | Q8: 51.21283 | R8: 16.792816 | S8: 2.6305565 | T8: 100
A9: 1997 | B9: Age group | C9: 41-64 | D9: Very unfair | E9: 31.807994 | H9: Male | I9: 27.855128 | J9: 51.033787 | K9: 18.09151 | L9: 3.0195752 | M9: 100 | O9: Country
A10: 1997 | B10: Age group | C10: 65+ | D10: Very unfair | E10: 32.054369 | H10: Age group | O10: Argentina | P10: 38.378035 | Q10: 50.660419 | R10: 10.135151 | S10: 0.82639481 | T10: 100
A11: 1997 | B11: Gender | C11: Female | D11: Very unfair | E11: 30.198123 | H11: 15-24 | I11: 25.257491 | J11: 52.015379 | K11: 19.642796 | L11: 3.0843346 | M11: 100 | O11: Bolivia | P11: 17.768688 | Q11: 55.871419 | R11: 23.881611 | S11: 2.4782814 | T11: 100
A12: 1997 | B12: Gender | C12: Male | D12: Very unfair | E12: 28.045609 | H12: 25-40 | I12: 28.33838 | J12: 51.349399 | K12: 17.287895 | L12: 3.0243258 | M12: 100 | O12: Brazil | P12: 31.814982 | Q12: 53.745601 | R12: 12.941176 | S12: 1.4982403 | T12: 100
A13: 1997 | B13: Civil Status | C13: Not married | D13: Very unfair | E13: 29.627672 | H13: 41-64 | I13: 29.181638 | J13: 51.73338 | K13: 16.307041 | L13: 2.777942 | M13: 100 | O13: Chile | P13: 40.195058 | Q13: 49.935273 | R13: 8.423197 | S13: 1.4464719 | T13: 100
A14: 1997 | B14: Civil Status | C14: Married | D14: Very unfair | E14: 28.639406 | H14: 65+ | I14: 28.785714 | J14: 51.600661 | K14: 17.133383 | L14: 2.4802423 | M14: 100 | O14: Colombia | P14: 35.132966 | Q14: 51.206936 | R14: 11.398651 | S14: 2.2614466 | T14: 100
A15: 1997 | B15: Religion | C15: Not catholic | D15: Very unfair | E15: 29.726872 | H15: Civil Status | O15: Costa Rica | P15: 23.184244 | Q15: 53.550694 | R15: 20.118587 | S15: 3.1464744 | T15: 100
A16: 1997 | B16: Religion | C16: Catholic | D16: Very unfair | E16: 29.047379 | H16: Married | I16: 28.153396 | J16: 51.931417 | K16: 17.140133 | L16: 2.7750537 | M16: 100 | O16: Dominican Rep. | P16: 32.447075 | Q16: 46.488766 | R16: 17.508156 | S16: 3.5560028 | T16: 100
A17: 1997 | B17: Type of employment | C17: Employer | D17: Very unfair | E17: 29.502255 | H17: Not married | I17: 27.732327 | J17: 51.334649 | K17: 17.871945 | L17: 3.0610786 | M17: 100 | O17: Ecuador | P17: 21.550526 | Q17: 47.580815 | R17: 27.376605 | S17: 3.4920537 | T17: 100
A18: 1997 | B18: Type of employment | C18: Employee | D18: Very unfair | E18: 28.432231 | H18: Religion | O18: El Salvador | P18: 22.670799 | Q18: 53.037649 | R18: 20.583574 | S18: 3.7079772 | T18: 100
A19: 1997 | B19: Type of employment | C19: Self-employed | D19: Very unfair | E19: 28.488324 | H19: Catholic | I19: 28.151103 | J19: 51.743653 | K19: 17.214878 | L19: 2.8903658 | M19: 100 | O19: Guatemala | P19: 28.261135 | Q19: 51.372785 | R19: 16.702112 | S19: 3.6639678 | T19: 100
A20: 1997 | B20: Type of employment | C20: Unemployed | D20: Very unfair | E20: 30.389675 | H20: Not catholic | I20: 27.53534 | J20: 51.468244 | K20: 18.079992 | L20: 2.9164243 | M20: 100 | O20: Honduras | P20: 28.856116 | Q20: 53.464497 | R20: 14.266908 | S20: 3.4124799 | T20: 100
A21: 1997 | B21: City size | C21: Under 100,000 | D21: Very unfair | H21: Education level | O21: Mexico | P21: 32.183474 | Q21: 49.857506 | R21: 15.217644 | S21: 2.7413756 | T21: 100
A22: 1997 | B22: City size | C22: 100,000 to 1,000,000 | D22: Very unfair | H22: Complete Primary | I22: 27.575163 | J22: 51.584857 | K22: 17.865565 | L22: 2.9744145 | M22: 100 | O22: Nicaragua | P22: 18.938521 | Q22: 51.671168 | R22: 24.232022 | S22: 5.1582887 | T22: 100
A23: 1997 | B23: City size | C23: More than 1,000,000 | D23: Very unfair | H23: Complete Secondary | I23: 27.620497 | J23: 52.050793 | K23: 17.71419 | L23: 2.6145195 | M23: 100 | O23: Panama | P23: 27.230298 | Q23: 48.114393 | R23: 20.29491 | S23: 4.3603991 | T23: 100
A24: 1997 | B24: Country | C24: Argentina | D24: Very unfair | E24: 54.739539 | H24: Complete Tertiary | I24: 28.689698 | J24: 52.899415 | K24: 15.645987 | L24: 2.7648992 | M24: 100 | O24: Paraguay | P24: 37.31618 | Q24: 48.917233 | R24: 11.910754 | S24: 1.8558329 | T24: 100
A25: 1997 | B25: Country | C25: Bolivia | D25: Very unfair | E25: 23.840206 | H25: Less than Primary | I25: 28.743028 | J25: 50.915665 | K25: 17.338661 | L25: 3.0026468 | M25: 100 | O25: Peru | P25: 24.83119 | Q25: 62.010226 | R25: 11.785309 | S25: 1.373275 | T25: 100
A26: 1997 | B26: Country | C26: Brazil | D26: Very unfair | E26: 38.52459 | H26: Type of employment | O26: Uruguay | P26: 18.257051 | Q26: 57.497818 | R26: 22.606483 | S26: 1.6386472 | T26: 100
A27: 1997 | B27: Country | C27: Chile | D27: Very unfair | E27: 34.456807 | H27: Employee | I27: 28.111582 | J27: 51.47569 | K27: 17.464852 | L27: 2.9478764 | M27: 100 | O27: Venezuela | P27: 23.529664 | Q27: 42.888048 | R27: 26.64192 | S27: 6.9403683 | T27: 100
A28: 1997 | B28: Country | C28: Colombia | D28: Very unfair | E28: 32.517524 | H28: Employer | I28: 27.105547 | J28: 52.523158 | K28: 17.545831 | L28: 2.8254632 | M28: 100
A29: 1997 | B29: Country | C29: Costa Rica | D29: Very unfair | E29: 15.314402 | H29: Self-employed | I29: 27.859621 | J29: 51.068111 | K29: 17.891306 | L29: 3.1809625 | M29: 100
A30: 1997 | B30: Country | C30: Dominican Rep. | D30: Very unfair | H30: Unemployed | I30: 30.610005 | J30: 51.525346 | K30: 14.949833 | L30: 2.9148168 | M30: 100
A31: 1997 | B31: Country | C31: Ecuador | D31: Very unfair | E31: 32.508834 | H31: City size
A32: 1997 | B32: Country | C32: Guatemala | D32: Very unfair | E32: 24.757804 | H32: 100,000 to 1,000,000 | I32: 26.227543 | J32: 51.748459 | K32: 19.143678 | L32: 2.8803201 | M32: 100
A33: 1997 | B33: Country | C33: Honduras | D33: Very unfair | E33: 15.686275 | H33: More than 1,000,000 | I33: 29.363797 | J33: 51.21283 | K33: 16.792816 | L33: 2.6305565 | M33: 100
A34: 1997 | B34: Country | C34: Mexico | D34: Very unfair | E34: 32.033426 | H34: Under 100,000 | I34: 26.510548 | J34: 52.653527 | K34: 18.463691 | L34: 2.3722331 | M34: 100
A35: 1997 | B35: Country | C35: Nicaragua | D35: Very unfair | E35: 19.28934 | H35: Country
A36: 1997 | B36: Country | C36: Panama | D36: Very unfair | E36: 20.620621 | H36: Argentina | I36: 38.378035 | J36: 50.660419 | K36: 10.135151 | L36: 0.82639481 | M36: 100
A37: 1997 | B37: Country | C37: Peru | D37: Very unfair | E37: 28.795299 | H37: Bolivia | I37: 17.768688 | J37: 55.871419 | K37: 23.881611 | L37: 2.4782814 | M37: 100
A38: 1997 | B38: Country | C38: Paraguay | D38: Very unfair | E38: 35.670608 | H38: Brazil | I38: 31.814982 | J38: 53.745601 | K38: 12.941176 | L38: 1.4982403 | M38: 100
A39: 1997 | B39: Country | C39: El Salvador | D39: Very unfair | E39: 16.565657 | H39: Chile | I39: 40.195058 | J39: 49.935273 | K39: 8.423197 | L39: 1.4464719 | M39: 100
A40: 1997 | B40: Country | C40: Uruguay | D40: Very unfair | E40: 26.48553 | H40: Colombia | I40: 35.132966 | J40: 51.206936 | K40: 11.398651 | L40: 2.2614466 | M40: 100
...

Sheet TableA4
C2: Mean | F2: Standard Dev. | I2: Observations
C3: Latinob. | D3: SEDLAC | F3: Latinob. | G3: SEDLAC | I3: Latinob. | J3: SEDLAC
B4: Sociodemographic
B5: Age | C5: 40.58685 | D5: 42.67552 | F5: 16.42827 | G5: 17.24923 | I5: 14855 | J5: 1004894
B6: Male (%) | C6: 48.97399 | D6: 47.62876 | F6: 0.4999115 | G6: 0.4994377 | I6: 14855 | J6: 1004894
B7: Married or civil union (%) | C7: 56.76954 | D7: 36.41195 | F7: 0.4954129 | G7: 0.4811826 | I7: 14804 | J7: 915117
B8: Education and Labor market
B9: Literate (%) | C9: 91.18438 | D9: 92.16613 | F9: 0.2835314 | G9: 0.2687039 | I9: 14855 | J9: 1004744
B10: Secondary education or more (%) | C10: 38.82803 | D10: 46.1051 | F10: 0.4873753 | G10: 0.4984809 | I10: 14855 | J10: 1001672
B11: Economically active (%) | C11: 65.13925 | D11: 68.66426 | F11: 0.4765455 | G11: 0.4638585 | I11: 14855 | J11: 1004718
B12: Unemployed (%) | C12: 5.78053 | D12: 4.08153 | F12: 0.2333828 | G12: 0.1978623 | I12: 14855 | J12: 1004718
B13: Assets and Services
B14: Access to a sewage (%) | C14: 68.75961 | D14: 63.41043 | F14: 0.4634903 | G14: 0.4816807 | I14: 13799 | J14: 975726
B15: Car (%) | C15: 26.36856 | D15: 21.09075 | F15: 0.4406498 | G15: 0.4079532 | I15: 11612 | J15: 643350
B16: Computer (%) | C16: 46.54755 | D16: 47.818 | F16: 0.4988262 | G16: 0.4995239 | I16: 12747 | J16: 894003
B17: Fridge (%) | C17: 82.75588 | D17: 88.88924 | F17: 0.3777783 | G17: 0.3142655 | I17: 12763 | J17: 894003
B18: Homeowner (%) | C18: 74.08795 | D18: 69.63561 | F18: 0.4381667 | G18: 0.459831 | I18: 14761 | J18: 1003306
B19: Mobile (%) | C19: 86.90916 | D19: 91.77911 | F19: 0.3373134 | G19: 0.2746828 | I19: 12754 | J19: 896079
B20: Washing machine (%) | C20: 60.49299 | D20: 56.87503 | F20: 0.4888864 | G20: 0.4952511 | I20: 11816 | J20: 848350
B21: Landline (%) | C21: 40.21651 | D21: 39.47329 | F21: 0.4903542 | G21: 0.4887935 | I21: 12736 | J21: 896425

Sheet TableB1
B2: Share of the voting age population represented by Latinobarómetro's survey every year
C4: 1997 | D4: 2001 | E4: 2002 | F4: 2007 | G4: 2009 | H4: 2010 | I4: 2011 | J4: 2013 | K4: 2015
B5: Argentina | C5: 68 | D5: 75 | E5: 75 | F5: 100 | G5: 100 | H5: 100 | I5: 100 | J5: 100 | K5: 100
B6: Bolivia | C6: 32 | D6: 52 | E6: 100 | F6: 100 | G6: 100 | H6: 100 | I6: 100 | J6: 100 | K6: 100
B7: Brazil | C7: 11.58 | D7: 100 | E7: 100 | F7: 100 | G7: 100 | H7: 100 | I7: 100 | J7: 100 | K7: 100
B8: Chile | C8: 70 | D8: 70 | E8: 70 | F8: 100 | G8: 100 | H8: 100 | I8: 100 | J8: 100 | K8: 100
B9: Colombia | C9: 25 | D9: 70.9 | E9: 50.5 | F9: 100 | G9: 99.9 | H9: 100 | I9: 100 | J9: 100 | K9: 100
B10: Costa Rica | C10: 100 | D10: 100 | E10: 100 | F10: 100 | G10: 100 | H10: 100 | I10: 100 | J10: 100 | K10: 100
B11: Dominican Republic | C11: N/A | D11: N/A | E11: N/A | F11: 100 | G11: 100 | H11: 100 | I11: 100 | J11: 100 | K11: 100
B12: Ecuador | C12: 96.8 | D12: 96.8 | E12: 100 | F12: 100 | G12: 100 | H12: 100 | I12: 100 | J12: 100 | K12: 100
B13: El Salvador | C13: 64.5 | D13: 100 | E13: 100 | F13: 100 | G13: 100 | H13: 100 | I13: 100 | J13: 100 | K13: 100
B14: Guatemala | C14: 100 | D14: 100 | E14: 100 | F14: 96.7 | G14: 100 | H14: 100 | I14: 100 | J14: 100 | K14: 100
B15: Honduras | C15: 100 | D15: 100 | E15: 100 | F15: 98.4 | G15: 100 | H15: 99 | I15: 99 | J15: 99 | K15: 99
B16: Mexico | C16: 93 | D16: 88.3 | E16: 95 | F16: 100 | G16: 100 | H16: 100 | I16: 100 | J16: 100 | K16: 100
B17: Nicaragua | C17: 100 | D17: 100 | E17: 100 | F17: 99.8 | G17: 100 | H17: 100 | I17: 100 | J17: 100 | K17: 100
B18: Panama | C18: 100 | D18: 100 | E18: 100 | F18: 99.2 | G18: 99.2 | H18: 99 | I18: 99 | J18: 99 | K18: 99
B19: Paraguay | C19: 46 | D19: 46 | E19: 46 | F19: 100 | G19: 100 | H19: 100 | I19: 100 | J19: 100 | K19: 100
B20: Peru | C20: 52 | D20: 52 | E20: 100 | F20: 100 | G20: 100 | H20: 100 | I20: 100 | J20: 100 | K20: 100
B21: Uruguay | C21: 80 | D21: 80 | E21: 80 | F21: 100 | G21: 100 | H21: 100 | I21: 100 | J21: 100 | K21: 100
B22: Venezuela | C22: 100 | D22: 100 | E22: 100 | F22: 100 | G22: 93.2 | H22: 100 | I22: 100 | J22: 100 | K22: 100
B23: Weighted average | C23: 68.33336 | D23: 85.88055 | E23: 90.99698 | F23: 99.882562 | G23: 99.98608 | H23: 99.979295 | I23: 99.97921 | J23: 99.97905 | K23: 99.97905

Sheet TableB2
B2: Country | C2: Year without household data | D2: Data point used instead
B3: Chile | C3: 1997 | D3: 1998
B4: Chile | C4: 2001 | D4: 2000
B5: Chile | C5: 2002 | D5: 2003
B6: Chile | C6: 2007 | D6: 2006
B7: Colombia | C7: 2007 | D7: 2008
B8: Ecuador | C8: 2002 | D8: 2003
B9: El Salvador | C9: 1997 | D9: 1998
B10: Guatemala | C10: 2001 | D10: 2000
B11: Guatemala | C11: 2015 | D11: 2014
B12: Mexico | C12: 1997 | D12: 1998
B13: Mexico | C13: 2001 | D13: 2000
B14: Mexico | C14: 2007 | D14: 2006
... B21: Venezuela | C21: 2013 | D21: 2012

Sheet TableB3
B2: Country | C2: Years interpolated
B3: Argentina | C3: 1997, 2001, and 2002
B4: Bolivia | C4: 2010
B5: Brazil | C5: 2010
B6: Chile | C6: 2010
B7: Colombia | C7: 1997
B8: Costa Rica | C8: 1997, 2001, 2002, 2007, and 2009
B9: Ecuador | C9: 1997, 2001
B10: Guatemala | C10: 1997, 2002, 2009, 2010, and 2013
B11: Mexico | C11: 2013
B12: Nicaragua | C12: 2002, 2010, 2011, and 2013
B13: Panama | C13: 1997, 2001, 2002, and 2007
B14: Peru | C14: 1997, 2001, 2002
B15: Venezuela | C15: 2015

Sheet FigA1
B1: Very Unfair | C1: Unfair | D1: Tax evasion | E1: Make a complaint to the media | F1: Signing a petition | G1: Unauthorized demonstrations | H1: Authorized demonstrations | I1: Complaint through social media | L1: Very Unfair | M1: Unfair
A2: arg | B2: 19.2464 | C2: 78.53316 | D2: 3.089788 | E2: 7.363747 | F2: 21.06841 | G2: 4.949065 | H2: 14.64794 | I2: 8.493257 | K2: Tax evasion | L2: =+CORREL($B$2:$B$19,D2:D19) -> 0.11597375 | M2: =+CORREL($C$2:$C$19,D2:D19) -> 0.16897016
A3: bol | B3: 10.1869 | C3: 52.99066 | D3: 4.747775 | E3: 7.27449 | F3: 12.21154 | G3: 7.436399 | H3: 13.91304 | I3: 4.53202 | K3: Make a complaint to the media | L3: =+CORREL($B$2:$B$19,E2:E19) -> 0.010804042 | M3: =+CORREL($C$2:$C$19,E2:E19) -> 0.11876988
A4: bra | B4: 45.8776 | C4: 92.32653 | D4: 3.639515 | E4: 13.72385 | F4: 25.81182 | G4: 5.695142 | H4: 12.39601 | I4: 16.68085 | K4: Signing a petition | L4: =+CORREL($B$2:$B$19,F2:F19) -> 0.21580257 | M4: =+CORREL($C$2:$C$19,F2:F19) -> 0.39297498
A5: chl | B5: 46.4691 | C5: 94.94157 | D5: 3.621907 | E5: 4.523634 | F5: 12.90447 | G5: 9.253844 | H5: 10.39008 | I5: 8.565327 | K5: Unauthorized demonstrations | L5: =+CORREL($B$2:$B$19,G2:G19) -> 0.15148952 | M5: =+CORREL($C$2:$C$19,G2:G19) -> 0.17233097
A6: col | B6: 35.1713 | C6: 85.58937 | D6: 4.830393 | E6: 9.444656 | F6: 23.92353 | G6: 6.118063 | H6: 16.01069 | I6: 10.57167 | K6: Authorized demonstrations | L6: =+CORREL($B$2:$B$19,H2:H19) -> -0.02049808 | M6: =+CORREL($C$2:$C$19,H2:H19) -> 0.19743392
A7: cri | B7: 29.8047 | C7: 81.29497 | D7: 6.347555 | E7: 6.853583 | F7: 21.51767 | G7: 4.95356 | H7: 13.057 | I7: 13.10273 | K7: Complaint through social media | L7: =+CORREL($B$2:$B$19,I2:I19) -> 0.42685329 | M7: =+CORREL($C$2:$C$19,I2:I19) -> 0.47990838
A8: dom | B8: 22.3986 | C8: 74.40675 | D8: 7.173796 | E8: 12.11412 | F8: 25.96639 | G8: 8.611763 | H8: 15.78366 | I8: 9.314564
A9: ecu | B9: 12.6941 | C9: 46.21004 | D9: 2.532833 | E9: 3.554724 | F9: 6.617647 | G9: 1.299907 | H9: 2.509294 | I9: 3.145853
A10: gtm | B10: 30.0193 | C10: 78.60542 | D10: 5.871477 | E10: 3.451279 | F10: 16.13858 | G10: 1.681473 | H10: 8.834056 | I10: 3.758128
